Workbook

Sheet Hunter DPS
A1: Kaiju Health (kh) | B1: Hunters (n) | C1: Clip Size | D1: Attack Interval | E1: Reload Time | F1: Damage Per Round | G1: Mechanical DPS | H1: Skill Factor | I1: Effective DPS | J1: Time to Kill (s) | K1: TTK (minutes)
A2: 100000 | B2: 4 | C2: 2 | D2: 0.8 | E2: 1.8 | F2: 100 | G2: =(C2 * F2) / ((C2 - 1) * D2 + E2) -> 76.923077 | H2: 1 | I2: =G2 * H2 -> 76.923077 | J2: =A2 / (G2 *B2*H2) -> 325 | K2: =J2 / 60 -> 5.4166667
H3: 0.9 | I3: =G2 * H3 -> 69.230769 | J3: =A2 / (I2 * B2) -> 325 | K3: =J3 / 60 -> 5.4166667
H4: 0.8 | I4: =G2 * H4 -> 61.538462 | J4: =A2 / (G2 *B2*H4) -> 406.25 | K4: =J4 / 60 -> 6.7708333
H5: 0.7 | I5: =G2 * H5 -> 53.846154 | J5: =A2 / (G2 *B2*H5) -> 464.28571 | K5: =J5 / 60 -> 7.7380952
H6: 0.6 | I6: =G2 * H6 -> 46.153846 | J6: =A2 / (G2 *B2*H6) -> 541.66667 | K6: =J6 / 60 -> 9.0277778
H7: 0.5 | I7: =G2 * H7 -> 38.461538 | J7: =A2 / (G2 *B2*H7) -> 650 | K7: =J7 / 60 -> 10.833333
H8: 0.4 | I8: =G2 * H8 -> 30.769231 | J8: =A2 / (G2 *B2*H8) -> 812.5 | K8: =J8 / 60 -> 13.541667
H9: 0.3 | I9: =G2 * H9 -> 23.076923 | J9: =A2 / (G2 *B2*H9) -> 1083.3333 | K9: =J9 / 60 -> 18.055556
H10: 0.2 | I10: =G2 * H10 -> 15.384615 | J10: =A2 / (G2 *B2*H10) -> 1625 | K10: =J10 / 60 -> 27.083333
H11: 0.1 | I11: =G2 * H11 -> 7.6923077 | J11: =A2 / (G2 *B2*H11) -> 3250 | K11: =J11 / 60 -> 54.166667

Sheet Kaiju Sim
A1: Kaiju DPS | B1: Base Efficiency | C1: Doom Target | D1: Efficiency Variance | G1: Kaiju Win Time | I1: Time To Win | J1: Seed
A2: 300 | B2: 0.7 | C2: 7000 | D2: 0.3 | I2: {=INDEX(G12:G300, MATCH(TRUE, F12:F300 >= $C$2, 0))} -> 77.131369 | J2: =ROW() -> 2
A5: Type | B5: Spawn % | C5: Health | D5: Doom
A6: Small | B6: 0.6 | C6: 150 | D6: 50
A7: Medium | B7: 0.3 | C7: 500 | D7: 150
A8: Large | B8: 0.1 | C8: 1000 | D8: 500
A11: Building Type | B11: Health | C11: Doom Gain | D11: Efficiency | E11: Time to Destroy | F11: Total Doom | G11: Total Time
A12: =IF(RAND() + ROW()/100000<$B$6,"Small",IF(RAND() + ROW()/100000<$B$6+$B$7,"Medium","Large")) -> Medium | B12: =IF(A12="Small",$C$6,IF(A12="Medium",$C$7,$C$8)) -> 500 | C12: =IF(A12="Small",$D$6,IF(A12="Medium",$D$7,$D$8)) -> 150 | D12: =$B$2 * (1 - $D$2/2 + RAND() + ROW()/100000*$D$2) -> 0.89863777 | E12: =B12 / ($A$2 * D12) -> 1.854659 | F12: =C12 -> 150 | G12: =E12 -> 1.854659
A13: =IF(RAND() + ROW()/100000<$B$6,"Small",IF(RAND() + ROW()/100000<$B$6+$B$7,"Medium","Large")) -> Small | B13: =IF(A13="Small",$C$6,IF(A13="Medium",$C$7,$C$8)) -> 150 | C13: =IF(A13="Small",$D$6,IF(A13="Medium",$D$7,$D$8)) -> 50 | D13: =$B$2 * (1 - $D$2/2 + RAND() + ROW()/100000*$D$2) -> 0.97120154 | E13: =B13 / ($A$2 * D13) -> 0.5148262 | F13: =F12 + C13 -> 200 | G13: =G12 + E13 -> 2.3694852
A14: =IF(RAND() + ROW()/100000<$B$6,"Small",IF(RAND() + ROW()/100000<$B$6+$B$7,"Medium","Large")) -> Medium | B14: =IF(A14="Small",$C$6,IF(A14="Medium",$C$7,$C$8)) -> 500 | C14: =IF(A14="Small",$D$6,IF(A14="Medium",$D$7,$D$8)) -> 150 | D14: =$B$2 * (1 - $D$2/2 + RAND() + ROW()/100000*$D$2) -> 0.81444277 | E14: =B14 / ($A$2 * D14) -> 2.0463889 | F14: =F13 + C14 -> 350 | G14: =G13 + E14 -> 4.4158742
A15: =IF(RAND() + ROW()/100000<$B$6,"Small",IF(RAND() + ROW()/100000<$B$6+$B$7,"Medium","Large")) -> Small | B15: =IF(A15="Small",$C$6,IF(A15="Medium",$C$7,$C$8)) -> 150 | C15: =IF(A15="Small",$D$6,IF(A15="Medium",$D$7,$D$8)) -> 50 | D15: =$B$2 * (1 - $D$2/2 + RAND() + ROW()/100000*$D$2) -> 0.93936582 | E15: =B15 / ($A$2 * D15) -> 0.532274 | F15: =F14 + C15 -> 400 | G15: =G14 + E15 -> 4.9481482
A16: =IF(RAND() + ROW()/100000<$B$6,"Small",IF(RAND() + ROW()/100000<$B$6+$B$7,"Medium","Large")) -> Small | B16: =IF(A16="Small",$C$6,IF(A16="Medium",$C$7,$C$8)) -> 150 | C16: =IF(A16="Small",$D$6,IF(A16="Medium",$D$7,$D$8)) -> 50 | D16: =$B$2 * (1 - $D$2/2 + RAND() + ROW()/100000*$D$2) -> 0.88323144 | E16: =B16 / ($A$2 * D16) -> 0.56610304 | F16: =F15 + C16 -> 450 | G16: =G15 + E16 -> 5.5142512
A17: =IF(RAND() + ROW()/100000<$B$6,"Small",IF(RAND() + ROW()/100000<$B$6+$B$7,"Medium","Large")) -> Small | B17: =IF(A17="Small",$C$6,IF(A17="Medium",$C$7,$C$8)) -> 150 | C17: =IF(A17="Small",$D$6,IF(A17="Medium",$D$7,$D$8)) -> 50 | D17: =$B$2 * (1 - $D$2/2 + RAND() + ROW()/100000*$D$2) -> 0.97557865 | E17: =B17 / ($A$2 * D17) -> 0.51251634 | F17: =F16 + C17 -> 500 | G17: =G16 + E17 -> 6.0267675
A18: =IF(RAND() + ROW()/100000<$B$6,"Small",IF(RAND() + ROW()/100000<$B$6+$B$7,"Medium","Large")) -> Medium | B18: =IF(A18="Small",$C$6,IF(A18="Medium",$C$7,$C$8)) -> 500 | C18: =IF(A18="Small",$D$6,IF(A18="Medium",$D$7,$D$8)) -> 150 | D18: =$B$2 * (1 - $D$2/2 + RAND() + ROW()/100000*$D$2) -> 1.0981031 | E18: =B18 / ($A$2 * D18) -> 1.5177689 | F18: =F17 + C18 -> 650 | G18: =G17 + E18 -> 7.5445364
A19: =IF(RAND() + ROW()/100000<$B$6,"Small",IF(RAND() + ROW()/100000<$B$6+$B$7,"Medium","Large")) -> Medium | B19: =IF(A19="Small",$C$6,IF(A19="Medium",$C$7,$C$8)) -> 500 | C19: =IF(A19="Small",$D$6,IF(A19="Medium",$D$7,$D$8)) -> 150 | D19: =$B$2 * (1 - $D$2/2 + RAND() + ROW()/100000*$D$2) -> 0.99467163 | E19: =B19 / ($A$2 * D19) -> 1.6755949 | F19: =F18 + C19 -> 800 | G19: =G18 + E19 -> 9.2201313
A20: =IF(RAND() + ROW()/100000<$B$6,"Small",IF(RAND() + ROW()/100000<$B$6+$B$7,"Medium","Large")) -> Small | B20: =IF(A20="Small",$C$6,IF(A20="Medium",$C$7,$C$8)) -> 150 | C20: =IF(A20="Small",$D$6,IF(A20="Medium",$D$7,$D$8)) -> 50 | D20: =$B$2 * (1 - $D$2/2 + RAND() + ROW()/100000*$D$2) -> 0.60157416 | E20: =B20 / ($A$2 * D20) -> 0.83115272 | F20: =F19 + C20 -> 850 | G20: =G19 + E20 -> 10.051284
A21: =IF(RAND() + ROW()/100000<$B$6,"Small",IF(RAND() + ROW()/100000<$B$6+$B$7,"Medium","Large")) -> Medium | B21: =IF(A21="Small",$C$6,IF(A21="Medium",$C$7,$C$8)) -> 500 | C21: =IF(A21="Small",$D$6,IF(A21="Medium",$D$7,$D$8)) -> 150 | D21: =$B$2 * (1 - $D$2/2 + RAND() + ROW()/100000*$D$2) -> 0.88680306 | E21: =B21 / ($A$2 * D21) -> 1.8794101 | F21: =F20 + C21 -> 1000 | G21: =G20 + E21 -> 11.930694
A22: =IF(RAND() + ROW()/100000<$B$6,"Small",IF(RAND() + ROW()/100000<$B$6+$B$7,"Medium","Large")) -> Large | B22: =IF(A22="Small",$C$6,IF(A22="Medium",$C$7,$C$8)) -> 1000 | C22: =IF(A22="Small",$D$6,IF(A22="Medium",$D$7,$D$8)) -> 500 | D22: =$B$2 * (1 - $D$2/2 + RAND() + ROW()/100000*$D$2) -> 1.128566 | E22: =B22 / ($A$2 * D22) -> 2.9536008 | F22: =F21 + C22 -> 1500 | G22: =G21 + E22 -> 14.884295
A23: =IF(RAND() + ROW()/100000<$B$6,"Small",IF(RAND() + ROW()/100000<$B$6+$B$7,"Medium","Large")) -> Medium | B23: =IF(A23="Small",$C$6,IF(A23="Medium",$C$7,$C$8)) -> 500 | C23: =IF(A23="Small",$D$6,IF(A23="Medium",$D$7,$D$8)) -> 150 | D23: =$B$2 * (1 - $D$2/2 + RAND() + ROW()/100000*$D$2) -> 0.86312193 | E23: =B23 / ($A$2 * D23) -> 1.9309748 | F23: =F22 + C23 -> 1650 | G23: =G22 + E23 -> 16.81527
A24: =IF(RAND() + ROW()/100000<$B$6,"Small",IF(RAND() + ROW()/100000<$B$6+$B$7,"Medium","Large")) -> Small | B24: =IF(A24="Small",$C$6,IF(A24="Medium",$C$7,$C$8)) -> 150 | C24: =IF(A24="Small",$D$6,IF(A24="Medium",$D$7,$D$8)) -> 50 | D24: =$B$2 * (1 - $D$2/2 + RAND() + ROW()/100000*$D$2) -> 0.66715294 | E24: =B24 / ($A$2 * D24) -> 0.74945334 | F24: =F23 + C24 -> 1700 | G24: =G23 + E24 -> 17.564723
... A300: =IF(RAND() + ROW()/100000<$B$6,"Small",IF(RAND() + ROW()/100000<$B$6+$B$7,"Medium","Large")) -> Medium | B300: =IF(A300="Small",$C$6,IF(A300="Medium",$C$7,$C$8)) -> 500 | C300: =IF(A300="Small",$D$6,IF(A300="Medium",$D$7,$D$8)) -> 150 | D300: =$B$2 * (1 - $D$2/2 + RAND() + ROW()/100000*$D$2) -> 0.93492058 | E300: =B300 / ($A$2 * D300) -> 1.7826826 | F300: =F299 + C300 -> 30000 | G300: =G299 + E300 -> 333.83777
A320: =IF(RAND() + ROW()/100000<$B$6,"Small",IF(RAND() + ROW()/100000<$B$6+$B$7,"Medium","Large")) -> Medium | B320: =IF(A320="Small",$C$6,IF(A320="Medium",$C$7,$C$8)) -> 500 | C320: =IF(A320="Small",$D$6,IF(A320="Medium",$D$7,$D$8)) -> 150 | D320: =$B$2 * (1 - $D$2/2 + RAND() + ROW()/100000*$D$2) -> 1.2547476 | E320: =B320 / ($A$2 * D320) -> 1.3282884 | F320: =C320 -> 150 | G320: =E320 -> 1.3282884
A321: =IF(RAND() + ROW()/100000<$B$6,"Small",IF(RAND() + ROW()/100000<$B$6+$B$7,"Medium","Large")) -> Small | B321: =IF(A321="Small",$C$6,IF(A321="Medium",$C$7,$C$8)) -> 150 | C321: =IF(A321="Small",$D$6,IF(A321="Medium",$D$7,$D$8)) -> 50 | D321: =$B$2 * (1 - $D$2/2 + RAND() + ROW()/100000*$D$2) -> 0.73654144 | E321: =B321 / ($A$2 * D321) -> 0.67884843 | F321: =F320 + C321 -> 200 | G321: =G320 + E321 -> 2.0071368
A322: =IF(RAND() + ROW()/100000<$B$6,"Small",IF(RAND() + ROW()/100000<$B$6+$B$7,"Medium","Large")) -> Medium | B322: =IF(A322="Small",$C$6,IF(A322="Medium",$C$7,$C$8)) -> 500 | C322: =IF(A322="Small",$D$6,IF(A322="Medium",$D$7,$D$8)) -> 150 | D322: =$B$2 * (1 - $D$2/2 + RAND() + ROW()/100000*$D$2) -> 1.2074256 | E322: =B322 / ($A$2 * D322) -> 1.3803473 | F322: =F321 + C322 -> 350 | G322: =G321 + E322 -> 3.3874841
A323: =IF(RAND() + ROW()/100000<$B$6,"Small",IF(RAND() + ROW()/100000<$B$6+$B$7,"Medium","Large")) -> Small | B323: =IF(A323="Small",$C$6,IF(A323="Medium",$C$7,$C$8)) -> 150 | C323: =IF(A323="Small",$D$6,IF(A323="Medium",$D$7,$D$8)) -> 50 | D323: =$B$2 * (1 - $D$2/2 + RAND() + ROW()/100000*$D$2) -> 0.82379233 | E323: =B323 / ($A$2 * D323) -> 0.60694909 | F323: =F322 + C323 -> 400 | G323: =G322 + E323 -> 3.9944332
A324: =IF(RAND() + ROW()/100000<$B$6,"Small",IF(RAND() + ROW()/100000<$B$6+$B$7,"Medium","Large")) -> Small | B324: =IF(A324="Small",$C$6,IF(A324="Medium",$C$7,$C$8)) -> 150 | C324: =IF(A324="Small",$D$6,IF(A324="Medium",$D$7,$D$8)) -> 50 | D324: =$B$2 * (1 - $D$2/2 + RAND() + ROW()/100000*$D$2) -> 0.60906617 | E324: =B324 / ($A$2 * D324) -> 0.82092887 | F324: =F323 + C324 -> 450 | G324: =G323 + E324 -> 4.815362
A325: =IF(RAND() + ROW()/100000<$B$6,"Small",IF(RAND() + ROW()/100000<$B$6+$B$7,"Medium","Large")) -> Small | B325: =IF(A325="Small",$C$6,IF(A325="Medium",$C$7,$C$8)) -> 150 | C325: =IF(A325="Small",$D$6,IF(A325="Medium",$D$7,$D$8)) -> 50 | D325: =$B$2 * (1 - $D$2/2 + RAND() + ROW()/100000*$D$2) -> 1.2679996 | E325: =B325 / ($A$2 * D325) -> 0.39432188 | F325: =F324 + C325 -> 500 | G325: =G324 + E325 -> 5.2096839
A326: =IF(RAND() + ROW()/100000<$B$6,"Small",IF(RAND() + ROW()/100000<$B$6+$B$7,"Medium","Large")) -> Small | B326: =IF(A326="Small",$C$6,IF(A326="Medium",$C$7,$C$8)) -> 150 | C326: =IF(A326="Small",$D$6,IF(A326="Medium",$D$7,$D$8)) -> 50 | D326: =$B$2 * (1 - $D$2/2 + RAND() + ROW()/100000*$D$2) -> 1.124657 | E326: =B326 / ($A$2 * D326) -> 0.44457998 | F326: =F325 + C326 -> 550 | G326: =G325 + E326 -> 5.6542639
A327: =IF(RAND() + ROW()/100000<$B$6,"Small",IF(RAND() + ROW()/100000<$B$6+$B$7,"Medium","Large")) -> Medium | B327: =IF(A327="Small",$C$6,IF(A327="Medium",$C$7,$C$8)) -> 500 | C327: =IF(A327="Small",$D$6,IF(A327="Medium",$D$7,$D$8)) -> 150 | D327: =$B$2 * (1 - $D$2/2 + RAND() + ROW()/100000*$D$2) -> 0.7021797 | E327: =B327 / ($A$2 * D327) -> 2.3735615 | F327: =F326 + C327 -> 700 | G327: =G326 + E327 -> 8.0278253
A328: =IF(RAND() + ROW()/100000<$B$6,"Small",IF(RAND() + ROW()/100000<$B$6+$B$7,"Medium","Large")) -> Medium | B328: =IF(A328="Small",$C$6,IF(A328="Medium",$C$7,$C$8)) -> 500 | C328: =IF(A328="Small",$D$6,IF(A328="Medium",$D$7,$D$8)) -> 150 | D328: =$B$2 * (1 - $D$2/2 + RAND() + ROW()/100000*$D$2) -> 0.84585466 | E328: =B328 / ($A$2 * D328) -> 1.9703937 | F328: =F327 + C328 -> 850 | G328: =G327 + E328 -> 9.998219
A329: =IF(RAND() + ROW()/100000<$B$6,"Small",IF(RAND() + ROW()/100000<$B$6+$B$7,"Medium","Large")) -> Small | B329: =IF(A329="Small",$C$6,IF(A329="Medium",$C$7,$C$8)) -> 150 | C329: =IF(A329="Small",$D$6,IF(A329="Medium",$D$7,$D$8)) -> 50 | D329: =$B$2 * (1 - $D$2/2 + RAND() + ROW()/100000*$D$2) -> 1.0644141 | E329: =B329 / ($A$2 * D329) -> 0.46974198 | F329: =F328 + C329 -> 900 | G329: =G328 + E329 -> 10.467961
A330: =IF(RAND() + ROW()/100000<$B$6,"Small",IF(RAND() + ROW()/100000<$B$6+$B$7,"Medium","Large")) -> Small | B330: =IF(A330="Small",$C$6,IF(A330="Medium",$C$7,$C$8)) -> 150 | C330: =IF(A330="Small",$D$6,IF(A330="Medium",$D$7,$D$8)) -> 50 | D330: =$B$2 * (1 - $D$2/2 + RAND() + ROW()/100000*$D$2) -> 1.267374 | E330: =B330 / ($A$2 * D330) -> 0.39451653 | F330: =F329 + C330 -> 950 | G330: =G329 + E330 -> 10.862478
A331: =IF(RAND() + ROW()/100000<$B$6,"Small",IF(RAND() + ROW()/100000<$B$6+$B$7,"Medium","Large")) -> Medium | B331: =IF(A331="Small",$C$6,IF(A331="Medium",$C$7,$C$8)) -> 500 | C331: =IF(A331="Small",$D$6,IF(A331="Medium",$D$7,$D$8)) -> 150 | D331: =$B$2 * (1 - $D$2/2 + RAND() + ROW()/100000*$D$2) -> 1.1510822 | E331: =B331 / ($A$2 * D331) -> 1.4479129 | F331: =F330 + C331 -> 1100 | G331: =G330 + E331 -> 12.31039
A332: =IF(RAND() + ROW()/100000<$B$6,"Small",IF(RAND() + ROW()/100000<$B$6+$B$7,"Medium","Large")) -> Small | B332: =IF(A332="Small",$C$6,IF(A332="Medium",$C$7,$C$8)) -> 150 | C332: =IF(A332="Small",$D$6,IF(A332="Medium",$D$7,$D$8)) -> 50 | D332: =$B$2 * (1 - $D$2/2 + RAND() + ROW()/100000*$D$2) -> 1.0731242 | E332: =B332 / ($A$2 * D332) -> 0.46592929 | F332: =F331 + C332 -> 1150 | G332: =G331 + E332 -> 12.77632
... A608: =IF(RAND() + ROW()/100000<$B$6,"Small",IF(RAND() + ROW()/100000<$B$6+$B$7,"Medium","Large")) -> Medium | B608: =IF(A608="Small",$C$6,IF(A608="Medium",$C$7,$C$8)) -> 500 | C608: =IF(A608="Small",$D$6,IF(A608="Medium",$D$7,$D$8)) -> 150 | D608: =$B$2 * (1 - $D$2/2 + RAND() + ROW()/100000*$D$2) -> 0.71950397 | E608: =B608 / ($A$2 * D608) -> 2.3164106 | F608: =F607 + C608 -> 29700 | G608: =G607 + E608 -> 329.49637
A628: =IF(RAND() + ROW()/100000<$B$6,"Small",IF(RAND() + ROW()/100000<$B$6+$B$7,"Medium","Large")) -> Medium | B628: =IF(A628="Small",$C$6,IF(A628="Medium",$C$7,$C$8)) -> 500 | C628: =IF(A628="Small",$D$6,IF(A628="Medium",$D$7,$D$8)) -> 150 | D628: =$B$2 * (1 - $D$2/2 + RAND() + ROW()/100000*$D$2) -> 0.92780042 | E628: =B628 / ($A$2 * D628) -> 1.7963633 | F628: =C628 -> 150 | G628: =E628 -> 1.7963633
A629: =IF(RAND() + ROW()/100000<$B$6,"Small",IF(RAND() + ROW()/100000<$B$6+$B$7,"Medium","Large")) -> Small | B629: =IF(A629="Small",$C$6,IF(A629="Medium",$C$7,$C$8)) -> 150 | C629: =IF(A629="Small",$D$6,IF(A629="Medium",$D$7,$D$8)) -> 50 | D629: =$B$2 * (1 - $D$2/2 + RAND() + ROW()/100000*$D$2) -> 0.73680993 | E629: =B629 / ($A$2 * D629) -> 0.67860106 | F629: =F628 + C629 -> 200 | G629: =G628 + E629 -> 2.4749644
A630: =IF(RAND() + ROW()/100000<$B$6,"Small",IF(RAND() + ROW()/100000<$B$6+$B$7,"Medium","Large")) -> Small | B630: =IF(A630="Small",$C$6,IF(A630="Medium",$C$7,$C$8)) -> 150 | C630: =IF(A630="Small",$D$6,IF(A630="Medium",$D$7,$D$8)) -> 50 | D630: =$B$2 * (1 - $D$2/2 + RAND() + ROW()/100000*$D$2) -> 0.99405567 | E630: =B630 / ($A$2 * D630) -> 0.50298994 | F630: =F629 + C630 -> 250 | G630: =G629 + E630 -> 2.9779543
A631: =IF(RAND() + ROW()/100000<$B$6,"Small",IF(RAND() + ROW()/100000<$B$6+$B$7,"Medium","Large")) -> Small | B631: =IF(A631="Small",$C$6,IF(A631="Medium",$C$7,$C$8)) -> 150 | C631: =IF(A631="Small",$D$6,IF(A631="Medium",$D$7,$D$8)) -> 50 | D631: =$B$2 * (1 - $D$2/2 + RAND() + ROW()/100000*$D$2) -> 1.0634244 | E631: =B631 / ($A$2 * D631) -> 0.47017919 | F631: =F630 + C631 -> 300 | G631: =G630 + E631 -> 3.4481335
A632: =IF(RAND() + ROW()/100000<$B$6,"Small",IF(RAND() + ROW()/100000<$B$6+$B$7,"Medium","Large")) -> Small | B632: =IF(A632="Small",$C$6,IF(A632="Medium",$C$7,$C$8)) -> 150 | C632: =IF(A632="Small",$D$6,IF(A632="Medium",$D$7,$D$8)) -> 50 | D632: =$B$2 * (1 - $D$2/2 + RAND() + ROW()/100000*$D$2) -> 0.7708894 | E632: =B632 / ($A$2 * D632) -> 0.64860147 | F632: =F631 + C632 -> 350 | G632: =G631 + E632 -> 4.096735
...

Sheet Match Results
A1: Run # | B1: Kaiju Time | C1: Result | D1: Win Rate
A2: =ROW()-1 -> 1 | B2: {=INDEX('Kaiju Sim'!G12:G300, MATCH(TRUE,'Kaiju Sim'!F12:F300 >= 'Kaiju Sim'!$C$2,0) )} -> 77.131369 | C2: =IF(B2 < E6, "Kaiju", "Hunters") -> Hunters | D2: =COUNTIF(C2:C1001,"Kaiju") / 1000 -> 0
A3: =ROW()-1 -> 2 | B3: {=INDEX('Kaiju Sim'!G13:G301, MATCH(TRUE,'Kaiju Sim'!F13:F301 >= 'Kaiju Sim'!$C$2,0) )} -> 77.131369
A4: =ROW()-1 -> 3 | B4: {=INDEX('Kaiju Sim'!G14:G302, MATCH(TRUE,'Kaiju Sim'!F14:F302 >= 'Kaiju Sim'!$C$2,0) )} -> 77.131369
A5: =ROW()-1 -> 4 | B5: {=INDEX('Kaiju Sim'!G15:G303, MATCH(TRUE,'Kaiju Sim'!F15:F303 >= 'Kaiju Sim'!$C$2,0) )} -> 77.131369
A6: =ROW()-1 -> 5 | B6: {=INDEX('Kaiju Sim'!G16:G304, MATCH(TRUE,'Kaiju Sim'!F16:F304 >= 'Kaiju Sim'!$C$2,0) )} -> 77.131369
A7: =ROW()-1 -> 6 | B7: {=INDEX('Kaiju Sim'!G17:G305, MATCH(TRUE,'Kaiju Sim'!F17:F305 >= 'Kaiju Sim'!$C$2,0) )} -> 77.131369
A8: =ROW()-1 -> 7 | B8: {=INDEX('Kaiju Sim'!G18:G306, MATCH(TRUE,'Kaiju Sim'!F18:F306 >= 'Kaiju Sim'!$C$2,0) )} -> 77.131369
A9: =ROW()-1 -> 8 | B9: {=INDEX('Kaiju Sim'!G19:G307, MATCH(TRUE,'Kaiju Sim'!F19:F307 >= 'Kaiju Sim'!$C$2,0) )} -> 77.131369
A10: =ROW()-1 -> 9 | B10: {=INDEX('Kaiju Sim'!G20:G308, MATCH(TRUE,'Kaiju Sim'!F20:F308 >= 'Kaiju Sim'!$C$2,0) )} -> 77.131369
A11: =ROW()-1 -> 10 | B11: {=INDEX('Kaiju Sim'!G21:G309, MATCH(TRUE,'Kaiju Sim'!F21:F309 >= 'Kaiju Sim'!$C$2,0) )} -> 77.131369
A12: =ROW()-1 -> 11 | B12: {=INDEX('Kaiju Sim'!G22:G310, MATCH(TRUE,'Kaiju Sim'!F22:F310 >= 'Kaiju Sim'!$C$2,0) )} -> 77.131369
A13: =ROW()-1 -> 12 | B13: {=INDEX('Kaiju Sim'!G23:G311, MATCH(TRUE,'Kaiju Sim'!F23:F311 >= 'Kaiju Sim'!$C$2,0) )} -> 77.131369
A14: =ROW()-1 -> 13 | B14: {=INDEX('Kaiju Sim'!G24:G312, MATCH(TRUE,'Kaiju Sim'!F24:F312 >= 'Kaiju Sim'!$C$2,0) )} -> 77.131369
... A1000: =ROW()-1 -> 999 | B1000: {=INDEX('Kaiju Sim'!G1010:G1298, MATCH(TRUE,'Kaiju Sim'!F1010:F1298 >= 'Kaiju Sim'!$C$2,0) )} -> 85.411811
